2020-12-06 05:27:50,017 INFO    MainThread:18538 [wandb_setup.py:_flush():68] setting env: {}
2020-12-06 05:27:50,017 INFO    MainThread:18538 [wandb_setup.py:_flush():68] multiprocessing start_methods=fork,spawn,forkserver
2020-12-06 05:27:50,017 INFO    MainThread:18538 [wandb_setup.py:_flush():68] setting login settings: {}
2020-12-06 05:27:50,017 INFO    MainThread:18538 [wandb_init.py:_log_setup():302] Logging user logs to /home/syseo/workspace/FIVO_Gumbel/wandb/run-20201206_052750-1e7kwqql/logs/debug.log
2020-12-06 05:27:50,017 INFO    MainThread:18538 [wandb_init.py:_log_setup():303] Logging internal logs to /home/syseo/workspace/FIVO_Gumbel/wandb/run-20201206_052750-1e7kwqql/logs/debug-internal.log
2020-12-06 05:27:50,031 WARNING MainThread:18538 [wandb_init.py:init():589] interrupted
Traceback (most recent call last):
  File "/home/syseo/anaconda3/envs/jericho/lib/python3.7/site-packages/wandb/sdk/wandb_init.py", line 569, in init
    run = wi.init()
  File "/home/syseo/anaconda3/envs/jericho/lib/python3.7/site-packages/wandb/sdk/wandb_init.py", line 364, in init
    use_redirect=use_redirect,
  File "/home/syseo/anaconda3/envs/jericho/lib/python3.7/site-packages/wandb/sdk/backend/backend.py", line 81, in ensure_launched
    self.wandb_process.start()
  File "/home/syseo/anaconda3/envs/jericho/lib/python3.7/multiprocessing/process.py", line 112, in start
    self._popen = self._Popen(self)
  File "/home/syseo/anaconda3/envs/jericho/lib/python3.7/multiprocessing/context.py", line 284, in _Popen
    return Popen(process_obj)
  File "/home/syseo/anaconda3/envs/jericho/lib/python3.7/multiprocessing/popen_spawn_posix.py", line 32, in __init__
    super().__init__(process_obj)
  File "/home/syseo/anaconda3/envs/jericho/lib/python3.7/multiprocessing/popen_fork.py", line 20, in __init__
    self._launch(process_obj)
  File "/home/syseo/anaconda3/envs/jericho/lib/python3.7/multiprocessing/popen_spawn_posix.py", line 59, in _launch
    cmd, self._fds)
  File "/home/syseo/anaconda3/envs/jericho/lib/python3.7/multiprocessing/util.py", line 432, in spawnv_passfds
    False, False, None)
KeyboardInterrupt
2020-12-06 05:27:50,034 INFO    MainThread:18538 [internal.py:handle_exit():138] Internal process exited
